<?xml version="1.0" encoding="UTF-8"?>

<robot name="littledog" xmlns:xsi="http://www.w3.org/2001/XMLSchema-instance"
 xsi:schemaLocation="http://drake.mit.edu drake-distro/drake/doc/drakeURDF.xsd"
 xmlns="http://drake.mit.edu">

    <gazebo>
        <plugin name="gazebo_ros_control" filename="libgazebo_ros_control.so">
            <robotNamespace>/littledog</robotNamespace>
        </plugin>
    </gazebo>

  <link name="body">
    <inertial>
      <mass value="1.800000" />
      <inertia ixx="0.001625" ixy="0" ixz="0" iyy="0.009178" iyz="0" izz="0.008794" />
    </inertial>
    <collision>
        <origin xyz="0 0 0" rpy="0 0 0"/>
        <geometry>
        <mesh filename="package://littledog/urdf/meshes/body.stl" scale=".0254 .0254 .0254" />
        </geometry>
    </collision>
    <visual>
      <geometry>
        <mesh filename="package://littledog/urdf/meshes/body.stl" scale=".0254 .0254 .0254" />
      </geometry>
      <material name="black">
      	<color rgba="0.1 0.1 0.1 1" />
      </material>
    </visual>
  </link>

  <gazebo reference="body">
        <kp>1000.0</kp>
        <kd>1000.0</kd>
        <mu1>0.5</mu1>
        <mu2>0.5</mu2>
        <!--<material>Gazebo/Blue</material>-->
  </gazebo>

  <link name="front_left_hip">
    <inertial>
      <origin xyz="0.000000 0.002900 0.000000" rpy="0 0 0" />
      <mass value="0.062300" />
      <inertia ixx="0.000004" ixy="0" ixz="0" iyy="0.000015" iyz="0" izz="0.000015" />
    </inertial>
    <collision>
        <origin xyz="0 0 0" rpy="0 0 0"/>
        <geometry>
          <mesh filename="package://littledog/urdf/meshes/front_left_hip.stl" scale=".0254 .0254 .0254"/>
        </geometry>
    </collision>
    <visual>
      <origin xyz="0 0 0" rpy="0 0 0" />
      <geometry>
        <mesh filename="package://littledog/urdf/meshes/front_left_hip.stl" scale=".0254 .0254 .0254"/>
      </geometry>
      <material name="black" />
    </visual>
  </link>

  <gazebo reference="front_left_hip">
        <kp>1000.0</kp>
        <kd>1000.0</kd>
        <mu1>0.5</mu1>
        <mu2>0.5</mu2>
        <material>Gazebo/Blue</material>
  </gazebo>

  <joint name="front_left_hip_roll" type="revolute">
    <parent link="body" />
    <child link="front_left_hip" />
    <origin xyz="0.101000 0.036250 0.000000" />
    <axis xyz="1 0 0" />
    <limit lower="-0.6" upper="0.6" effort="0.1" velocity="0.005"/>
  </joint>
  

  
  <link name="front_left_upper_leg">
    <inertial>
      <origin xyz="0.000000 0.000000 -0.016600" rpy="0 0 0" />
      <mass value="0.127900" />
      <inertia ixx="0.000082" ixy="0" ixz="0" iyy="0.000089" iyz="0" izz="0.000015" />
    </inertial>
    <collision>
        <origin xyz="0 0 0" rpy="0 0 0"/>
        <geometry>
        <mesh filename="package://littledog/urdf/meshes/front_left_upper.stl" scale=".0254 .0254 .0254"/>
        </geometry>
    </collision>
    <visual>
      <origin xyz="0 0 0" rpy="0 0 0" />
      <geometry>
        <mesh filename="package://littledog/urdf/meshes/front_left_upper.stl" scale=".0254 .0254 .0254"/>
      </geometry>
      <material name="black" />
    </visual>
  </link>

    <gazebo reference="front_left_upper_leg">
        <kp>1000.0</kp>
        <kd>1000.0</kd>
        <mu1>0.5</mu1>
        <mu2>0.5</mu2>
        <material>Gazebo/Blue</material>
    </gazebo>


  <joint name="front_left_hip_pitch" type="revolute">
    <parent link="front_left_hip" />
    <child link="front_left_upper_leg" />
    <origin xyz="0 0.0236 0" />
    <axis xyz="0 1 0" />
    <limit lower="-3.5" upper="2.4" effort="0.1" velocity="0.005"/>
  </joint>  

  
  <link name="front_left_lower_leg"> 
    <inertial>
      <origin xyz="0.000000 0.000000 -0.020200" rpy="0 0 0" />
      <mass value="0.046400" />
      <inertia ixx="0.000038" ixy="0" ixz="0" iyy="0.000035" iyz="0" izz="0.000004" />
    </inertial>
    <collision>
        <origin xyz="0 0 0" rpy="0 0 0"/>
        <geometry>
        <mesh filename="package://littledog/urdf/meshes/front_left_lower.stl" scale="0.0254 0.0254 0.0254"/>
        </geometry>
    </collision>
    <visual>
      <origin xyz="0 0 0" rpy="0 0 0" />
      <geometry>
        <mesh filename="package://littledog/urdf/meshes/front_left_lower.stl" scale="0.0254 0.0254 0.0254"/>
      </geometry>
      <material name="black" />
    </visual>  
  </link>
  
  <gazebo reference="front_left_lower_leg">
        <kp>1000.0</kp>
        <kd>1000.0</kd>
        <mu1>0.5</mu1>
        <mu2>0.5</mu2>
        <material>Gazebo/Blue</material>
  </gazebo>

  <joint name="front_left_knee" type="revolute">
    <parent link="front_left_upper_leg" />
    <child link="front_left_lower_leg" />
    <origin xyz="0 0 -0.0751" />
    <axis xyz="0 1 0" />
    <limit lower="-3.1" upper="1.0" effort="0.1" velocity="0.005"/>
  </joint>


  <!-- <frame link="front_left_lower_leg" name="front_left_foot_center" xyz="-0.0265 0 -0.0985"/> -->

  <link name="front_right_hip">
    <inertial>
      <origin xyz="0.000000 -0.002900 0.000000" rpy="0 0 0" />
      <mass value="0.062300" />
      <inertia ixx="0.000004" ixy="0" ixz="0" iyy="0.000015" iyz="0" izz="0.000015" />
    </inertial>
    <collision>
        <origin xyz="0 0 0" rpy="0 0 0"/>
        <geometry>
        <mesh filename="package://littledog/urdf/meshes/front_right_hip.stl" scale="0.0254 0.0254 0.0254"/>
        </geometry>
    </collision>
    <visual>
      <origin xyz="0 0 0" rpy="0 0 0" />
      <geometry>
        <mesh filename="package://littledog/urdf/meshes/front_right_hip.stl" scale="0.0254 0.0254 0.0254"/>
      </geometry>
      <material name="black" />
    </visual>
   </link>
  <gazebo reference="front_right_hip">
        <kp>1000.0</kp>
        <kd>1000.0</kd>
        <mu1>0.5</mu1>
        <mu2>0.5</mu2>
        <material>Gazebo/Blue</material>
  </gazebo>

  <joint name="front_right_hip_roll" type="revolute">
    <parent link="body" />
    <child link="front_right_hip" />
    <origin xyz="0.101000 -0.036250 0.000000" />
    <axis xyz="1 0 0" />
    <limit lower="-.6" upper=".6" effort="0.1" velocity="0.005"/>
  </joint>
  

  <link name="front_right_upper_leg">
    <inertial>
      <origin xyz="0.000000 0.000000 -0.016600" rpy="0 0 0" />
      <mass value="0.127900" />
      <inertia ixx="0.000082" ixy="0" ixz="0" iyy="0.000089" iyz="0" izz="0.000015" />
    </inertial>
    <collision>
        <origin xyz="0 0 0" rpy="0 0 0"/>
        <geometry>
        <mesh filename="package://littledog/urdf/meshes/front_right_upper.stl" scale="0.0254 0.0254 0.0254"/>
        </geometry>
    </collision>
    <visual>
      <origin xyz="0 0 0" rpy="0 0 0" />
      <geometry>
        <mesh filename="package://littledog/urdf/meshes/front_right_upper.stl" scale="0.0254 0.0254 0.0254"/>
      </geometry>
      <material name="black"/>
    </visual>
  </link>

    <gazebo reference="front_right_upper_leg">
        <kp>1000.0</kp>
        <kd>1000.0</kd>
        <mu1>0.5</mu1>
        <mu2>0.5</mu2>
        <material>Gazebo/Blue</material>
    </gazebo>

  <joint name="front_right_hip_pitch" type="revolute">
    <parent link="front_right_hip" />
    <child link="front_right_upper_leg" />
    <origin xyz="0 -0.0236 0" />
    <axis xyz="0 1 0" />
    <limit lower="-3.5" upper="2.4" effort="0.1" velocity="0.005"/>
  </joint>
  
  
  <link name="front_right_lower_leg"> 
    <inertial>
      <origin xyz="0.000000 0.000000 -0.020200" rpy="0 0 0" />
      <mass value="0.046400" />
      <inertia ixx="0.000038" ixy="0" ixz="0" iyy="0.000035" iyz="0" izz="0.000004" />
    </inertial>
    <collision>
        <origin xyz="0 0 0" rpy="0 0 0"/>
        <geometry>
        <mesh filename="package://littledog/urdf/meshes/front_right_lower.stl" scale="0.0254 0.0254 0.0254"/>
        </geometry>
    </collision>
    <visual>
      <origin xyz="0 0 0" rpy="0 0 0" />
      <geometry>
        <mesh filename="package://littledog/urdf/meshes/front_right_lower.stl" scale="0.0254 0.0254 0.0254"/>
      </geometry>
      <material name="black"/>
    </visual> 
  </link>

    <gazebo reference="front_right_lower_leg">
        <kp>1000.0</kp>
        <kd>1000.0</kd>
        <mu1>0.5</mu1>
        <mu2>0.5</mu2>
        <material>Gazebo/Blue</material>
    </gazebo>

  <joint name="front_right_knee" type="revolute">
    <parent link="front_right_upper_leg" />
    <child link="front_right_lower_leg" />
    <origin xyz="0 0 -0.0751" />
    <axis xyz="0 1 0" />
    <limit lower="-3.1" upper="1.0" effort="0.1" velocity="0.005"/>
  </joint>
  
  
  <!-- <frame link="front_right_lower_leg" name="front_right_foot_center" xyz="-0.0265 0 -0.0985"/> -->
  
  <link name="back_left_hip">
    <inertial>
      <origin xyz="0.000000 0.002900 0.000000" rpy="0 0 0" />
      <mass value="0.062300" />
      <inertia ixx="0.000004" ixy="0" ixz="0" iyy="0.000015" iyz="0" izz="0.000015" />
    </inertial>
    <collision>
        <origin xyz="0 0 0" rpy="0 0 0"/>
        <geometry>
        <mesh filename="package://littledog/urdf/meshes/back_left_hip.stl" scale="0.0254 0.0254 0.0254"/>
        </geometry>
    </collision>
    <visual>
      <origin xyz="0 0 0" rpy="0 0 0" />
      <geometry>
        <mesh filename="package://littledog/urdf/meshes/back_left_hip.stl" scale="0.0254 0.0254 0.0254"/>
      </geometry>
      <material name="black" />
    </visual>
  </link>

    <gazebo reference="back_left_hip">
        <kp>1000.0</kp>
        <kd>1000.0</kd>
        <mu1>0.5</mu1>
        <mu2>0.5</mu2>
        <material>Gazebo/Blue</material>
    </gazebo>

  <joint name="back_left_hip_roll" type="revolute">
    <parent link="body" />
    <child link="back_left_hip" />
    <origin xyz="-0.101000 0.036250 0.000000" />
    <axis xyz="1 0 0" />
    <limit lower="-.6" upper=".6" effort="0.1" velocity="0.005"/>
  </joint>
   
  <link name="back_left_upper_leg">
    <inertial>
      <origin xyz="0.000000 0.000000 -0.016600" rpy="0 0 0" />
      <mass value="0.127900" />
      <inertia ixx="0.000082" ixy="0" ixz="0" iyy="0.000089" iyz="0" izz="0.000015" />
    </inertial>
    <collision>
        <origin xyz="0 0 0" rpy="0 0 0"/>
        <geometry>
        <mesh filename="package://littledog/urdf/meshes/back_left_upper.stl" scale="0.0254 0.0254 0.0254"/>
        </geometry>
    </collision>

    <visual>
      <origin xyz="0 0 0" rpy="0 0 0" />
      <geometry>
        <mesh filename="package://littledog/urdf/meshes/back_left_upper.stl" scale="0.0254 0.0254 0.0254"/>
      </geometry>
      <material name="black" />
    </visual>
  </link>
    <gazebo reference="back_left_upper_leg">
        <kp>1000.0</kp>
        <kd>1000.0</kd>
        <mu1>0.5</mu1>
        <mu2>0.5</mu2>
        <material>Gazebo/Blue</material>
    </gazebo>

  <joint name="back_left_hip_pitch" type="revolute">
    <parent link="back_left_hip" />
    <child link="back_left_upper_leg" />
    <origin xyz="0 0.0236 0" />
    <axis xyz="0 1 0" />
    <limit lower="-2.4" upper="3.5" effort="0.1" velocity="0.005"/>
  </joint>
  
  
  <link name="back_left_lower_leg"> 
    <inertial>
      <origin xyz="0.000000 0.000000 -0.020200" rpy="0 0 0" />
      <mass value="0.046400" />
      <inertia ixx="0.000038" ixy="0" ixz="0" iyy="0.000035" iyz="0" izz="0.000004" />
    </inertial>
    <collision>
        <origin xyz="0 0 0" rpy="0 0 0"/>
        <geometry>
        <mesh filename="package://littledog/urdf/meshes/back_left_lower.stl" scale="0.0254 0.0254 0.0254"/>
        </geometry>
    </collision>
    <visual>
      <origin xyz="0 0 0" rpy="0 0 0" />
      <geometry>
        <mesh filename="package://littledog/urdf/meshes/back_left_lower.stl" scale="0.0254 0.0254 0.0254"/>
      </geometry>
      <material name="black" />
    </visual>
  </link>

  <gazebo reference="back_left_lower_leg">
        <kp>1000.0</kp>
        <kd>1000.0</kd>
        <mu1>0.5</mu1>
        <mu2>0.5</mu2>
        <material>Gazebo/Blue</material>
  </gazebo>

  <joint name="back_left_knee" type="revolute">
    <parent link="back_left_upper_leg" />
    <child link="back_left_lower_leg" />
    <origin xyz="0 0 -0.0751" />
    <axis xyz="0 1 0" />
    <limit lower="-1.0" upper="3.1" effort="0.1" velocity="0.005"/>
  </joint>

  
  <!-- <frame link="back_left_lower_leg" name="back_left_foot_center" xyz="0.0265 0 -0.0985"/> -->
  
  <link name="back_right_hip">
    <inertial>
      <origin xyz="0.000000 -0.002900 0.000000" rpy="0 0 0" />
      <mass value="0.062300" />
      <inertia ixx="0.000004" ixy="0" ixz="0" iyy="0.000015" iyz="0" izz="0.000015" />
    </inertial>
    <collision>
        <origin xyz="0 0 0" rpy="0 0 0"/>
        <geometry>
        <mesh filename="package://littledog/urdf/meshes/back_right_hip.stl" scale="0.0254 0.0254 0.0254"/>
        </geometry>
    </collision>
    <visual>
      <origin xyz="0 0 0" rpy="0 0 0" />
      <geometry>
        <mesh filename="package://littledog/urdf/meshes/back_right_hip.stl" scale="0.0254 0.0254 0.0254"/>
      </geometry>
      <material name="black" />
    </visual>
  </link>

  <gazebo reference="back_right_hip">
        <kp>1000.0</kp>
        <kd>1000.0</kd>
        <mu1>0.5</mu1>
        <mu2>0.5</mu2>
        <material>Gazebo/Blue</material>
  </gazebo>

  <joint name="back_right_hip_roll" type="revolute">
    <parent link="body" />
    <child link="back_right_hip" />
    <origin xyz="-0.101000 -0.036250 0.000000" />
    <axis xyz="1 0 0" />
    <limit lower="-.6" upper=".6" effort="0.1" velocity="0.005"/>
  </joint>
    
  <link name="back_right_upper_leg">
    <inertial>
      <origin xyz="0.000000 0.000000 -0.016600" rpy="0 0 0" />
      <mass value="0.127900" />
      <inertia ixx="0.000082" ixy="0" ixz="0" iyy="0.000089" iyz="0" izz="0.000015" />
    </inertial>
    <collision>
        <origin xyz="0 0 0" rpy="0 0 0"/>
        <geometry>
        <mesh filename="package://littledog/urdf/meshes/back_right_upper.stl" scale="0.0254 0.0254 0.0254"/>
        </geometry>
    </collision>    
    <visual>
      <origin xyz="0 0 0" rpy="0 0 0" />
      <geometry>
        <mesh filename="package://littledog/urdf/meshes/back_right_upper.stl" scale="0.0254 0.0254 0.0254"/>
      </geometry>
      <material name="black" />
    </visual>
  </link>

  <gazebo reference="back_right_upper_leg">
        <kp>1000.0</kp>
        <kd>1000.0</kd>
        <mu1>0.5</mu1>
        <mu2>0.5</mu2>
        <material>Gazebo/Blue</material>
  </gazebo>

  <joint name="back_right_hip_pitch" type="revolute">
    <parent link="back_right_hip" />
    <child link="back_right_upper_leg" />
    <origin xyz="0 -0.0207 0" />
    <axis xyz="0 1 0" />
    <limit lower="-2.4" upper="3.5" effort="0.1" velocity="0.005"/>
  </joint>
  
  
  <link name="back_right_lower_leg"> 
    <inertial>
      <origin xyz="0.000000 0.000000 -0.020200" rpy="0 0 0" />
      <mass value="0.046400" />
      <inertia ixx="0.000038" ixy="0" ixz="0" iyy="0.000035" iyz="0" izz="0.000004" />
    </inertial>
    <collision>
        <origin xyz="0 0 0" rpy="0 0 0"/>
        <geometry>
        <mesh filename="package://littledog/urdf/meshes/back_right_lower.stl" scale="0.0254 0.0254 0.0254"/>
        </geometry>
    </collision>        
    <visual>
      <origin xyz="0 0 0" rpy="0 0 0" />
      <geometry>
        <mesh filename="package://littledog/urdf/meshes/back_right_lower.stl" scale="0.0254 0.0254 0.0254"/>
      </geometry>
      <material name="black" />
    </visual>
  </link>
  <gazebo reference="back_right_lower_leg">
        <kp>1000.0</kp>
        <kd>1000.0</kd>
        <mu1>0.5</mu1>
        <mu2>0.5</mu2>
        <material>Gazebo/Blue</material>
  </gazebo>

  <joint name="back_right_knee" type="revolute">
    <parent link="back_right_upper_leg" />
    <child link="back_right_lower_leg" />
    <origin xyz="0 0 -0.0751" />
    <axis xyz="0 1 0" />
    <limit lower="-1.0" upper="3.1" effort="0.1" velocity="0.005"/>
  </joint>
  
  <!-- <frame link="back_right_lower_leg" name="back_right_foot_center" xyz="0.0265 0 -0.0985"/> -->

     <transmission name="front_left_hip_roll_trans">
      <type>transmission_interface/SimpleTransmission</type>
      <joint name="front_left_hip_roll">
        <hardwareInterface>hardware_interface/EffortJointInterface</hardwareInterface>
      </joint>
      <actuator name="front_left_hip_roll_Motor">
        <hardwareInterface>hardware_interface/EffortJointInterface</hardwareInterface>
        <mechanicalReduction>1</mechanicalReduction>
      </actuator>
    </transmission>

    <transmission name="front_left_hip_pitch_trans">
      <type>transmission_interface/SimpleTransmission</type>
      <joint name="front_left_hip_pitch">
        <hardwareInterface>hardware_interface/EffortJointInterface</hardwareInterface>
      </joint>
      <actuator name="front_left_hip_pitch_Motor">
        <hardwareInterface>hardware_interface/EffortJointInterface</hardwareInterface>
        <mechanicalReduction>1</mechanicalReduction>
      </actuator>
    </transmission>

    <transmission name="front_left_knee_trans">
      <type>transmission_interface/SimpleTransmission</type>
      <joint name="front_left_knee">
        <hardwareInterface>hardware_interface/EffortJointInterface</hardwareInterface>
      </joint>
      <actuator name="front_left_knee_Motor">
        <hardwareInterface>hardware_interface/EffortJointInterface</hardwareInterface>
        <mechanicalReduction>1</mechanicalReduction>
      </actuator>
    </transmission>

    <transmission name="front_right_hip_pitch_trans">
      <type>transmission_interface/SimpleTransmission</type>
      <joint name="front_right_hip_pitch">
        <hardwareInterface>hardware_interface/EffortJointInterface</hardwareInterface>
      </joint>
      <actuator name="front_right_hip_pitch_Motor">
        <hardwareInterface>hardware_interface/EffortJointInterface</hardwareInterface>
        <mechanicalReduction>1</mechanicalReduction>
      </actuator>
    </transmission>

    <transmission name="front_right_hip_roll_trans">
      <type>transmission_interface/SimpleTransmission</type>
      <joint name="front_right_hip_roll">
        <hardwareInterface>hardware_interface/EffortJointInterface</hardwareInterface>
      </joint>
      <actuator name="front_right_hip_roll_Motor">
        <hardwareInterface>hardware_interface/EffortJointInterface</hardwareInterface>
        <mechanicalReduction>1</mechanicalReduction>
      </actuator>
    </transmission>

    <transmission name="front_right_knee_trans">
      <type>transmission_interface/SimpleTransmission</type>
      <joint name="front_right_knee">
        <hardwareInterface>hardware_interface/EffortJointInterface</hardwareInterface>
      </joint>
      <actuator name="front_right_knee_Motor">
        <hardwareInterface>hardware_interface/EffortJointInterface</hardwareInterface>
        <mechanicalReduction>1</mechanicalReduction>
      </actuator>
    </transmission>

    <transmission name="back_left_hip_roll_trans">
      <type>transmission_interface/SimpleTransmission</type>
      <joint name="back_left_hip_roll">
        <hardwareInterface>hardware_interface/EffortJointInterface</hardwareInterface>
      </joint>
      <actuator name="back_left_hip_roll_Motor">
        <hardwareInterface>hardware_interface/EffortJointInterface</hardwareInterface>
        <mechanicalReduction>1</mechanicalReduction>
      </actuator>
    </transmission>

    <transmission name="back_left_hip_pitch_trans">
      <type>transmission_interface/SimpleTransmission</type>
      <joint name="back_left_hip_pitch">
        <hardwareInterface>hardware_interface/EffortJointInterface</hardwareInterface>
      </joint>
      <actuator name="back_left_hip_pitch_Motor">
        <hardwareInterface>hardware_interface/EffortJointInterface</hardwareInterface>
        <mechanicalReduction>1</mechanicalReduction>
      </actuator>
    </transmission>

    <transmission name="back_left_knee_trans">
      <type>transmission_interface/SimpleTransmission</type>
      <joint name="back_left_knee">
        <hardwareInterface>hardware_interface/EffortJointInterface</hardwareInterface>
      </joint>
      <actuator name="back_left_knee_Motor">
        <hardwareInterface>hardware_interface/EffortJointInterface</hardwareInterface>
        <mechanicalReduction>1</mechanicalReduction>
      </actuator>
    </transmission>

    <transmission name="back_right_hip_pitch_trans">
      <type>transmission_interface/SimpleTransmission</type>
      <joint name="back_right_hip_pitch">
        <hardwareInterface>hardware_interface/EffortJointInterface</hardwareInterface>
      </joint>
      <actuator name="back_right_hip_pitch_Motor">
        <hardwareInterface>hardware_interface/EffortJointInterface</hardwareInterface>
        <mechanicalReduction>1</mechanicalReduction>
      </actuator>
    </transmission>

    <transmission name="back_right_hip_roll_trans">
      <type>transmission_interface/SimpleTransmission</type>
      <joint name="back_right_hip_roll">
        <hardwareInterface>hardware_interface/EffortJointInterface</hardwareInterface>
      </joint>
      <actuator name="back_right_hip_roll_Motor">
        <hardwareInterface>hardware_interface/EffortJointInterface</hardwareInterface>
        <mechanicalReduction>1</mechanicalReduction>
      </actuator>
    </transmission>

    <transmission name="back_right_knee_trans">
      <type>transmission_interface/SimpleTransmission</type>
      <joint name="back_right_knee">
        <hardwareInterface>hardware_interface/EffortJointInterface</hardwareInterface>
      </joint>
      <actuator name="back_right_knee_Motor">
        <hardwareInterface>hardware_interface/EffortJointInterface</hardwareInterface>
        <mechanicalReduction>1</mechanicalReduction>
      </actuator>
    </transmission> 
</robot>