<?xml version="1.0"?>
<robot name="quadruped_leg"  xmlns:xacro="http://www.ros.org/wiki/xacro">

  <xacro:include filename="$(find spotmini)/urdf/trans.urdf.xacro"/>

  <material name="red">
    <color rgba="1.0 0.0 0.0 1.0"/>
  </material>
 <material name="green">
    <color rgba="0.0 1.0 0.0 1.0"/>
</material>  
<material name="blue">
    <color rgba="0.0 0.0 1.0 1.0"/>
</material>
<material name="white">
    <color rgba="1 1.0 1.0 1.0"/>
</material>


  <link name="base_link">
    <visual>
      <geometry>
        <box size="0.3 0.1 0.02"/>
        <origin xyz = "0 0 0.01" rpy =" 0 0 1.0"/>
      </geometry>
      <material name="blue"/>

    </visual>

    <inertial>
         <origin xyz="0 0 0.01" rpy="0 0 1.0"/>
         <mass value="1"/>
         <inertia ixx="0.11"  ixy="0"  ixz="0.0" iyy= "0.04" iyz="0" izz="0.02" />
       </inertial>
     <collision>
        <origin xyz = "0 0 1.50" rpy="0 0 0"/>
        <geometry>
          <box size="0.3 0.1 0.02"/>
        </geometry>
    </collision>
  </link>


  
  <link name="upperleg_M1_link">
    <visual>
      <geometry>
        <cylinder length="0.045" radius="0.01"/>
      </geometry>
      <origin rpy="0 0 0" xyz="0 0 -0.0225"/>
    </visual>

    <inertial>
        <origin rpy="0 0 0" xyz="0 0 -0.0225"/>
        <mass value="1"/>
         <inertia ixx="0.11"  ixy="0"  ixz="0.0" iyy= "0.04" iyz="0" izz="0.02" />
      </inertial>
     <collision>
        <origin rpy="0 0 0" xyz="0 0 -0.0225"/>
        <geometry>
          <cylinder length="0.045" radius="0.01"/>
        </geometry>
    </collision> 
  </link>
  
  <joint name="base_upperlegM1_joint" type="revolute">
    <axis xyz="0 1 0"/>
    <limit effort="10.0" lower="-0.39" upper="0.39" velocity="1.0"/>
    <parent link="base_link"/>
    <child link="upperleg_M1_link"/>
    <origin xyz="0.145 -0.045 -0.01"/>
  </joint>



  <link name="lowerleg_M1_link">
    <visual>
      <geometry>
        <cylinder length="0.05" radius="0.005"/>
      </geometry>
      <origin rpy="0 0 0" xyz="0 0 -0.025"/>
    </visual>

    <inertial>
        <origin rpy="0 0 0" xyz="0 0 -0.025"/>
        <mass value="1"/>
         <inertia ixx="0.11"  ixy="0"  ixz="0.0" iyy= "0.04" iyz="0" izz="0.02" />
      </inertial>
     <collision>
        <origin rpy="0 0 0" xyz="0 0 -0.025"/>
        <geometry>
          <cylinder length="0.05" radius="0.005"/>
        </geometry>
    </collision> 
  </link>
  
  <joint name="upperlegM1_lowerlegM1_joint" type="revolute">
    <axis xyz="0 1 0"/>
    <limit effort="10.0" lower="-0.39" upper="0.40" velocity="1.0"/>
    <parent link="upperleg_M1_link"/>
    <child link="lowerleg_M1_link"/>
    <origin xyz="0 0 -0.045"/>
  </joint>

  <!-- <joint name="upperlegM1_lowerlegM1_joint2" type="revolute">
    <axis xyz="0 0 1"/>
    <limit effort="10.0" lower="-0.39" upper="0.40" velocity="1.0"/>
    <parent link="upperleg_M1_link"/>
    <child link="lowerleg_M1_link"/>
    <origin xyz="0 0 -0.045"/>
  </joint> -->
  
  <link name="upperleg_M2_link">
    <visual>
      <geometry>
        <cylinder length="0.045" radius="0.01"/>
      </geometry>
      <origin rpy="0 0 0" xyz="0 0 -0.0225"/>
    </visual>
    <inertial>
        <origin rpy="0 0 0" xyz="0 0 -0.0225"/>
        <mass value="1"/>
         <inertia ixx="0.11"  ixy="0"  ixz="0.0" iyy= "0.04" iyz="0" izz="0.02" />
      </inertial>
     <collision>
        <origin rpy="0 0 0" xyz="0 0 -0.0225"/>
        <geometry>
          <cylinder length="0.045" radius="0.01"/>
        </geometry>
    </collision> 
  </link>
  


  <joint name="base_upperlegM2_joint" type="revolute">
    <axis xyz="0 1 0"/>
    <limit effort="10.0" lower="-1.57075" upper="1.57075" velocity="1.0"/>
    <parent link="base_link"/>
    <child link="upperleg_M2_link"/>
     <origin xyz="0.145 0.045 -0.01"/>
  </joint>


  <link name="lowerleg_M2_link">
    <visual>
      <geometry>
        <cylinder length="0.05" radius="0.005"/>
      </geometry>
      <origin rpy="0 0 0" xyz="0 0 -0.025"/>
    </visual>
    <inertial>
        <origin rpy="0 0 0" xyz="0 0 -0.025"/>
        <mass value="1"/>
         <inertia ixx="0.11"  ixy="0"  ixz="0.0" iyy= "0.04" iyz="0" izz="0.02" />
      </inertial>
     <collision>
        <origin rpy="0 0 0" xyz="0 0 -0.025"/>
        <geometry>
          <cylinder length="0.05" radius="0.005"/>
        </geometry>
    </collision> 

  </link>
  
  <joint name="upperlegM2_lowerlegM2_joint" type="revolute">
    <axis xyz="0 1 0"/>
    <limit effort="1.0" lower="-0.39" upper="0.39" velocity="1"/>
    <parent link="upperleg_M2_link"/>
    <child link="lowerleg_M2_link"/>
    <origin xyz="0 0 -0.045"/>
  </joint>


  <link name="upperleg_M3_link">
    <visual>
      <geometry>
        <cylinder length="0.045" radius="0.01"/>
      </geometry>
      <origin rpy="0 0 0" xyz="0 0 -0.0225"/>
    </visual>
    <inertial>
        <origin rpy="0 0 0" xyz="0 0 -0.0225"/>
        <mass value="1"/>
         <inertia ixx="0.11"  ixy="0"  ixz="0.0" iyy= "0.04" iyz="0" izz="0.02" />
      </inertial>
     <collision>
        <origin rpy="0 0 0" xyz="0 0 -0.0225"/>
        <geometry>
          <cylinder length="0.045" radius="0.01"/>
        </geometry>
    </collision>  
 
  </link>
  
  <joint name="base_upperlegM3_joint" type="revolute">
    <axis xyz="0 1 0"/>
    <limit effort="10.0" lower="-0.39" upper="0.39"  velocity="1.0"/>
    <parent link="base_link"/>
    <child link="upperleg_M3_link"/>
    <origin xyz="-0.145 -0.045 -0.01"/>
  </joint>

 
  <link name="lowerleg_M3_link">
    <visual>
      <geometry>
        <cylinder length="0.05" radius="0.005"/>
      </geometry>
      <origin rpy="0 0 0" xyz="0 0 -0.025"/>
    </visual>

    <inertial>
        <origin rpy="0 0 0" xyz="0 0 -0.025"/>
        <mass value="1"/>
         <inertia ixx="0.11"  ixy="0"  ixz="0.0" iyy= "0.04" iyz="0" izz="0.02" />
      </inertial>
     <collision>
        <origin rpy="0 0 0" xyz="0 0 -0.025"/>
        <geometry>
          <cylinder length="0.05" radius="0.005"/>
        </geometry>
    </collision>  

  </link>
  <joint name="upperlegM3_lowerlegM3_joint" type="revolute">
    <axis xyz="0 1 0"/>
    <limit effort="10.0"  lower="-0.39" upper="0.39" velocity="1.0"/>
    <parent link="upperleg_M3_link"/>
    <child link="lowerleg_M3_link"/>
    <origin xyz="0 0 -0.045"/>
  </joint>


  <link name="upperleg_M4_link">
    <visual>
      <geometry>
        <cylinder length="0.045" radius="0.01"/>
      </geometry>
      <origin rpy="0 0 0" xyz="0 0 -0.0225"/>
    </visual>

    <inertial>
        <origin rpy="0 0 0" xyz="0 0 -0.0225"/>
        <mass value="1"/>
         <inertia ixx="0.11"  ixy="0"  ixz="0.0" iyy= "0.04" iyz="0" izz="0.02" />
      </inertial>
     <collision>
        <origin rpy="0 0 0" xyz="0 0 -0.0225"/>
        <geometry>
          <cylinder length="0.045" radius="0.01"/>
        </geometry>
    </collision>  

  </link>
  
  <joint name="base_upperlegM4_joint" type="revolute">
    <axis xyz="0 1 0"/>
    <limit effort="10.0" lower="-0.39" upper="0.39" velocity="1.0"/>
    <parent link="base_link"/>
    <child link="upperleg_M4_link"/>
    <origin xyz="-0.145 0.045 -0.01"/>
  </joint>

 
  <link name="lowerleg_M4_link">
    <visual>
      <geometry>
        <cylinder length="0.05" radius="0.005"/>
      </geometry>
      <origin rpy="0 0 0" xyz="0 0 -0.025"/>
    </visual>
    <inertial>
        <origin rpy="0 0 0" xyz="0 0 -0.025"/>
        <mass value="1"/>
         <inertia ixx="0.11"  ixy="0"  ixz="0.0" iyy= "0.04" iyz="0" izz="0.02" />
      </inertial>
     <collision>
        <origin rpy="0 0 0" xyz="0 0 -0.025"/>
        <geometry>
          <cylinder length="0.05" radius="0.005"/>
        </geometry>
    </collision>  
  </link>
   
  <joint name="upperlegM4_lowerlegM4_joint" type="revolute">
    <axis xyz="0 1 0"/>
    <limit effort="10.0" lower="-0.39" upper="0.39" velocity="1.0"/>
    <parent link="upperleg_M4_link"/>
    <child link="lowerleg_M4_link"/>
    <origin xyz="0 0 -0.045"/>
  </joint>



</robot>