<?xml version="1.0"?>
<robot name="simple_example">

  <material name="blue">
    <color rgba="0 0 1 1"/>
  </material>

  <material name="red">
    <color rgba="1 0 0 1"/>
  </material>

  <material name="green">
    <color rgba="0 1 0 1"/>
  </material>

  <link name="base_link">
    
    <inertial>
        <mass value="10" />
        <inertia ixx="0.4" ixy="0.0" ixz="0.0" iyy="0.4" iyz="0.0" izz="0.2"/>
    </inertial>

    <collision>
      <geometry>
        <cylinder radius="0.15" length="0.1" />
      </geometry>
    </collision>
    
    <visual>
      <origin xyz="0.0 0 0.05" rpy="0 0 0" />
      <geometry>
        <cylinder radius="0.15" length="0.1" />
      </geometry>
    <material name="blue"/>    
    </visual>

  </link>
  <joint name="base_to_second_link" type="revolute">
    <axis xyz="0 0 1"/>
    <limit effort="1" lower="1.57" upper="-1.57" velocity="1.0"/>
    <parent link="base_link"/>
    <child link="second_link"/>
    <origin  xyz="0.0 0 0.1" rpy="0.0 0.0 1.57"/> 
  </joint>

  <link name="second_link">  
    <inertial>
        <mass value="0.18" />
        <inertia ixx="0.0002835" ixy="0.0" ixz="0.0" iyy="0.0002835" iyz="0.0" izz="0.000324" />
    </inertial>
    <collision>
      <geometry>
        <cylinder radius="0.10" length="0.2" />
      </geometry>
    </collision>
    <visual>
    <origin rpy="0.0 0.0 0.0" xyz="0.0 0.0 0.10" />
      <geometry>
        <cylinder radius="0.10" length="0.2" />
      </geometry>
    <material name="red"/>
    </visual>
  </link>

  <joint name="second_to_third_joint" type="revolute">
    <axis xyz="1 0 0"/>
    <limit effort="1" lower="1.57" upper="-1.57" velocity="1.0"/>
    <parent link="second_link"/>
    <child link="third_link"/>
    <origin  xyz="0.0 0 0.2" rpy="0.0 0.0 1.57"/> 
  </joint>


  <link name="third_link">
    
    <inertial>
        <mass value="0.18" />
        <inertia ixx="0.0002835" ixy="0.0" ixz="0.0" iyy="0.0002835" iyz="0.0" izz="0.000324" />
    </inertial>

    <collision>
      <geometry>
        <cylinder radius="0.08" length="0.15" />
      </geometry>
    </collision>

    <visual>
    <origin rpy="0.0 0 0.0" xyz="0.0 0.0 0.075" />
      <geometry>
        <cylinder radius="0.08" length="0.15"/>
      </geometry>
    <material name="green"/>
    </visual>
  </link>

  <joint name="third_to_fourth_joint" type="revolute">
    <axis xyz="1 0 0"/>
    <limit effort="1" lower="1.57" upper="-1.57" velocity="1.0"/>
    <parent link="third_link"/>
    <child link="fourth_link"/>
    <origin  xyz="0.0 0 0.15" rpy="0.0 0.0 1.57"/> 
  </joint>

  <link name="fourth_link"> 
    <inertial>
        <mass value="0.18" />
        <inertia ixx="0.0002835" ixy="0.0" ixz="0.0" iyy="0.0002835" iyz="0.0" izz="0.000324" />
    </inertial>

    <collision>
      <geometry>
        <cylinder radius="0.08" length="0.3" />
      </geometry>
    </collision>

    <visual>
    <origin rpy="0.0 0 0.0" xyz="0.0 0.0 0.15" />
      <geometry>
        <cylinder radius="0.06" length="0.3" />
      </geometry>
    <material name="blue"/>    
    </visual>
  </link>

  <joint name="fourth_to_fifth_joint" type="revolute">
    <axis xyz="1 0 0"/>
    <limit effort="1" lower="1.57" upper="-1.57" velocity="1.0"/>
    <parent link="fourth_link"/>
    <child link="fifth_link"/>
    <origin  xyz="0.0 0 0.3" rpy="0.0 0.0 1.57"/> 
  </joint>

  <link name="fifth_link"> 
    <inertial>
        <mass value="0.18" />
        <inertia ixx="0.0002835" ixy="0.0" ixz="0.0" iyy="0.0002835" iyz="0.0" izz="0.000324" />
    </inertial>

    <collision>
      <geometry>
        <cylinder radius="0.06" length="0.15" />
      </geometry>
    </collision>

    <visual>
    <origin rpy="0.0 0 0.0" xyz="0.0 0.0 0.075" />
      <geometry>
        <cylinder radius="0.06" length="0.15" />
      </geometry>
    <material name="green"/>    
    </visual>
  </link>

  <joint name="fifth_to_sixth_joint" type="revolute">
    <axis xyz="1 0 0"/>
    <limit effort="1" lower="1.57" upper="-1.57" velocity="1.0"/>
    <parent link="fifth_link"/>
    <child link="sixth_link"/>
    <origin  xyz="0.0 0 0.15" rpy="0.0 0.0 1.57"/> 
  </joint>


  <link name="sixth_link"> 
    <inertial>
        <mass value="0.18" />
        <inertia ixx="0.0002835" ixy="0.0" ixz="0.0" iyy="0.0002835" iyz="0.0" izz="0.000324" />
    </inertial>

    <collision>
      <geometry>
        <cylinder radius="0.06" length="0.10" />
      </geometry>
    </collision>

    <visual>
    <origin rpy="0.0 0 0.0" xyz="0.0 0.0 0.05" />
      <geometry>
        <cylinder radius="0.06" length="0.1" />
      </geometry>
    <material name="blue"/>    
    </visual>
  </link>





</robot>